Workbook

Sheet README
B2: Atelier Verde SAS — fictional dataset for a 13-week cash forecast
B3: Best Case Study Competition 2026 · Case 4: Financial Navigator by A352 · Data as at Friday 9 October 2026, 18:00
B4: ⚠ FICTIONAL DATA | C4: Every company, person, customer, supplier, bank, amount and date in this workbook is invented and simulated for the case study. Any resemblance to real entities is coincidental. Names of real public bodies or tax schemes (URSSAF, DGFiP, Chorus Pro, LCR, CA3) are used only to make the French payment calendar realistic.
B6: 1. Company overview
B7: Legal form & location | C7: SAS (simplified joint-stock company), workshop and offices in Villeurbanne, Lyon metropolitan area, France. Founded 2014 by two cabinet-makers; family-owned.
B8: What it does | C8: Designs and manufactures eco-designed furniture for workplaces and hotels: solid-oak and FSC birch-plywood desks, meeting tables, storage, acoustic felt panels and booths, and hotel-room furniture. Everything is made to order in its own workshop (CNC machining, sanding, water-based finishing, assembly).
B9: People | C9: 38 full-time employees: 26 in production, 4 in design/engineering, 3 in installation logistics, 5 in sales and admin. Finance team of two: a CFO (part-time, shared with a sister company) and an accountant.
B10: Size (fictional) | C10: Revenue ≈ €6.7M ex VAT forecast for 2026 (growth ≈ 8%). EBITDA ≈ €0.53M (≈ 8%), net profit ≈ €0.19M (≈ 2.8%). Profitable every year, but thin margins and lumpy cash flows. See 'PnL_Monthly'.
B11: How it makes money | C11: Make-to-order: a customer orders, Atelier Verde buys materials about 4 weeks ahead, produces, delivers and invoices on delivery. Customers then pay 30–60 days after the invoice — often later. So the company pays for timber and wages ~2–3 months before it gets paid. Growth makes this gap bigger.
B12: Customer segments (share of 2026 revenue) | C12: • Office fit-out contractors ≈ 45% — design-and-build firms refurbishing offices; 45–60 day terms; usually pay 10–25 days late (they wait for their own client to pay). • Furniture distributors ≈ 24% — reliable; one pays by LCR (automatic bill of exchange) exactly on the due date. • Public sector ≈ 10% — a university (legal limit 30 days) and a public hospital (legal limit 50 days); invoices go through the Chorus Pro portal; in practice the university pays ~10 days late and the hospital ~20 days late. • Hospitality projects ≈ 10% — hotel groups refurbishing whole hotels; few but very large invoices billed by milestone: 30% at order, 40% on delivery, 30% after installation. • Export distributor (Belgium) ≈ 7% — intra-EU sale, no French VAT. • Direct corporate client ≈ 4%.
B13: Suppliers & costs | C13: Materials ≈ 44% of revenue. Biggest single supplier: Holzwerk Bayern GmbH (Germany, timber & plywood, 30-day terms, intra-EU so no VAT is paid). Others: steel frames, acoustic felt, hardware, finishes, transport. Staff costs ≈ €2.4M per year (≈ 36%). Rent for the workshop, energy, an equipment lease and a bank loan for a CNC machine.
B14: Seasonality | C14: Peak September–November (companies spend year-end budgets on office refits). Slump in August (workshop closed two weeks). Christmas closure 24 Dec – 3 Jan. December payroll includes a 13th-month bonus.
B15: Cash calendar (who gets paid when) | C15: Salaries: last business day of the month · Social charges and income tax withheld: 15th of the following month · VAT (monthly CA3 return): ~24th of the following month · Corporate tax instalments: 15 Mar/Jun/Sep/Dec · Rent and insurance: quarterly in advance · Loan: 5th · Equipment lease: 10th · Supplier payment run: every Thursday, on or just before each due date.
B16: Banking | C16: Two accounts (main account via EBICS, card account via PSD2) — the kind of multibank set-up Financial Navigator connects to. Overdraft facility €150k on the main account. CFO's minimum cash buffer: €100k (≈ two weeks of payroll and charges).
B18: 2. The situation on 9 October 2026
B19: Cash | C19: €381,241 across both accounts. Open customer invoices: €1.41M incl. VAT, of which €167k overdue (DSO ≈ 67 days).
B20: Profit looks fine | C20: Q4 2026 is forecast at ≈ €182k net profit (strong October–November deliveries).
B21: …but cash is under pressure | C21: • Lumen Hospitality Group owes €230,400 (Hôtel Lumen Annecy delivery milestone), due 13 Nov 2026; a further €172,800 installation invoice will be issued 30 Oct, due 29 Dec. • A €155,000 Holzwerk Bayern bill (winter timber pre-order + materials for the new Azur Cannes & Antibes hotel project) is due 20 Nov and will be paid on Thu 19 Nov. • December carries the 13th-month bonus (€72k), a corporate tax instalment and property tax. • A planned €34,560 deposit on a new edge-banding machine is due 25 Nov (can be deferred). • Nova Interiors is paying slower and slower (≈ 22 days late in 2025 → ≈ 34 days late in Q3 2026). • Two invoices are disputed (transport damage claim; a hospital invoice rejected for a missing PO number).
B22: Why the CFO wants a tool | C22: From the end of June 2025 cash stayed below the €100k buffer for five weeks, and in the week of 28 July 2025 it slipped into the overdraft (−€38.2k) without anyone seeing it coming: a dividend, payroll, VAT and timber bills went out while summer receipts slowed. The current forecast is a spreadsheet rebuilt by hand once a month.
B24: 3. Sheets in this workbook
B25: Assumptions | C25: Assumption register: every parameter used by the forecast, with source, owner, date and confidence. Blue cells are inputs you can change.
B26: Data_Dictionary | C26: Meaning of every column.
B27: Bank_Accounts | C27: Balances at 9 Oct 2026 — the forecast's starting point.
B28: Bank_Weekly | C28: Weekly opening/closing balances, Apr 2025 – 9 Oct 2026 (80 weeks). Used to back-test the forecast.
B29: Bank_Transactions | C29: Every bank movement, Apr 2025 – 9 Oct 2026 (bank feed).
B30: Customers | C30: Customer master data, plus calculated payment behaviour (average days late, open balance).
B31: AR_Invoices | C31: All customer invoices since Jan 2025: paid ones with payment date and days late; open ones with days overdue.
B32: Order_Book | C32: Invoices planned during the 13 forecast weeks (confirmed orders, project milestones, and pipeline at 80% probability).
B33: Suppliers / AP_Bills | C33: Supplier master and supplier bills since Jan 2025 (paid and open with scheduled payment date).
B34: Committed_Purchases | C34: Purchase orders already placed whose bills will be paid within the forecast window — incl. the €155k Holzwerk bill.
B35: Scheduled_Payments | C35: Payroll, social charges, VAT, taxes, rent, loan, lease, energy, card spending and planned capex in the window.
B36: VAT_Returns | C36: Monthly VAT returns (output VAT − deductible VAT = net payable).
... B43: ▶ Data_Sources | C43: What each data attribute is based on: French regulation, Banque de France statistics, or a stated assumption.
B45: 4. Conventions
B46: Colours | C46: Blue text = input/assumption you can edit · Black = data or formula · Green = formula linking to another sheet · Yellow fill = key assumption.
B47: Units | C47: Euros. 'incl_vat' = amount actually paid/received in cash (VAT included); 'ex_vat' = amount in the P&L.
B48: Weeks | C48: Monday–Sunday. Forecast week 1 = Mon 12 Oct 2026; week 13 ends Sun 10 Jan 2027.
B49: Generated with | C49: Python (pandas, numpy, openpyxl) simulation with a fixed random seed, by Claude (Anthropic) at the participant's request. Payment delays are drawn from per-customer distributions, so history behaves like a real company's: noisy, seasonal, with occasional long delays.

Sheet Forecast_13W
A1: Atelier Verde SAS — 13-week cash forecast (as at Fri 9 Oct 2026)
A2: Fictional data. Cash basis, amounts incl. VAT. Expected values (pipeline orders × probability). Edit blue cells in 'Assumptions' (e.g. S01 Lumen delay) and everything below recalculates.
A4: Week | C4: 1 | D4: 2 | E4: 3 | F4: 4 | G4: 5 | H4: 6 | I4: 7 | J4: 8 | K4: 9 | L4: 10 | M4: 11 | N4: 12 | O4: 13 | P4: 13-week total
A5: Week starting (Monday) | C5: =Assumptions!$C$2+7*(C$4-1) -> 46307 | D5: =Assumptions!$C$2+7*(D$4-1) -> 46314 | E5: =Assumptions!$C$2+7*(E$4-1) -> 46321 | F5: =Assumptions!$C$2+7*(F$4-1) -> 46328 | G5: =Assumptions!$C$2+7*(G$4-1) -> 46335 | H5: =Assumptions!$C$2+7*(H$4-1) -> 46342 | I5: =Assumptions!$C$2+7*(I$4-1) -> 46349 | J5: =Assumptions!$C$2+7*(J$4-1) -> 46356 | ... O5: =Assumptions!$C$2+7*(O$4-1) -> 46391
A6: Week ending (Sunday) | C6: =C5+6 -> 46313 | D6: =D5+6 -> 46320 | E6: =E5+6 -> 46327 | F6: =F5+6 -> 46334 | G6: =G5+6 -> 46341 | H6: =H5+6 -> 46348 | I6: =I5+6 -> 46355 | J6: =J5+6 -> 46362 | ... O6: =O5+6 -> 46397
A8: BASE CASE — customers pay with their usual delays
A9: Opening balance | B9: W1 = Assumptions A03 | C9: =Assumptions!$C$4 -> 381240.65 | D9: =C36 -> 282840.5 | E9: =D36 -> 449176.92 | F9: =E36 -> 100857 | G9: =F36 -> 170790.53 | H9: =G36 -> 253974.51 | I9: =H36 -> 118636.62 | J9: =I36 -> 343376.38 | K9: =J36 -> 164325.06 | ... O9: =N36 -> 219892.39
A10: Receipts
A11: Office fit-out contractor | B11: SUMIFS on Forecast_Lines | C11: =SUMIFS(Forecast_Lines!$J$4:$J$377,Forecast_Lines!$D$4:$D$377,"Receipt",Forecast_Lines!$E$4:$E$377,"Customer – Office fit-out contractor",Forecast_Lines!$U$4:$U$377,"Yes",Forecast_Lines!$O$4:$O$377,C$4) -> 11748 | D11: =SUMIFS(Forecast_Lines!$J$4:$J$377,Forecast_Lines!$D$4:$D$377,"Receipt",Forecast_Lines!$E$4:$E$377,"Customer – Office fit-out contractor",Forecast_Lines!$U$4:$U$377,"Yes",Forecast_Lines!$O$4:$O$377,D$4) -> 105012 | E11: =SUMIFS(Forecast_Lines!$J$4:$J$377,Forecast_Lines!$D$4:$D$377,"Receipt",Forecast_Lines!$E$4:$E$377,"Customer – Office fit-out contractor",Forecast_Lines!$U$4:$U$377,"Yes",Forecast_Lines!$O$4:$O$377,E$4) -> 28500 | F11: =SUMIFS(Forecast_Lines!$J$4:$J$377,Forecast_Lines!$D$4:$D$377,"Receipt",Forecast_Lines!$E$4:$E$377,"Customer – Office fit-out contractor",Forecast_Lines!$U$4:$U$377,"Yes",Forecast_Lines!$O$4:$O$377,F$4) -> 70368 | G11: =SUMIFS(Forecast_Lines!$J$4:$J$377,Forecast_Lines!$D$4:$D$377,"Receipt",Forecast_Lines!$E$4:$E$377,"Customer – Office fit-out contractor",Forecast_Lines!$U$4:$U$377,"Yes",Forecast_Lines!$O$4:$O$377,G$4) -> 43836 | H11: =SUMIFS(Forecast_Lines!$J$4:$J$377,Forecast_Lines!$D$4:$D$377,"Receipt",Forecast_Lines!$E$4:$E$377,"Customer – Office fit-out contractor",Forecast_Lines!$U$4:$U$377,"Yes",Forecast_Lines!$O$4:$O$377,H$4) -> 73788 | I11: =SUMIFS(Forecast_Lines!$J$4:$J$377,Forecast_Lines!$D$4:$D$377,"Receipt",Forecast_Lines!$E$4:$E$377,"Customer – Office fit-out contractor",Forecast_Lines!$U$4:$U$377,"Yes",Forecast_Lines!$O$4:$O$377,I$4) -> 77616 | J11: =SUMIFS(Forecast_Lines!$J$4:$J$377,Forecast_Lines!$D$4:$D$377,"Receipt",Forecast_Lines!$E$4:$E$377,"Customer – Office fit-out contractor",Forecast_Lines!$U$4:$U$377,"Yes",Forecast_Lines!$O$4:$O$377,J$4) -> 34728 | ... O11: =SUMIFS(Forecast_Lines!$J$4:$J$377,Forecast_Lines!$D$4:$D$377,"Receipt",Forecast_Lines!$E$4:$E$377,"Customer – Office fit-out contractor",Forecast_Lines!$U$4:$U$377,"Yes",Forecast_Lines!$O$4:$O$377,O$4) -> 82622.4 | P11: =SUM(C11:O11) -> 879614.4
A12: Furniture distributor | B12: SUMIFS on Forecast_Lines | C12: =SUMIFS(Forecast_Lines!$J$4:$J$377,Forecast_Lines!$D$4:$D$377,"Receipt",Forecast_Lines!$E$4:$E$377,"Customer – Furniture distributor",Forecast_Lines!$U$4:$U$377,"Yes",Forecast_Lines!$O$4:$O$377,C$4) -> 7836 | D12: =SUMIFS(Forecast_Lines!$J$4:$J$377,Forecast_Lines!$D$4:$D$377,"Receipt",Forecast_Lines!$E$4:$E$377,"Customer – Furniture distributor",Forecast_Lines!$U$4:$U$377,"Yes",Forecast_Lines!$O$4:$O$377,D$4) -> 49944 | E12: =SUMIFS(Forecast_Lines!$J$4:$J$377,Forecast_Lines!$D$4:$D$377,"Receipt",Forecast_Lines!$E$4:$E$377,"Customer – Furniture distributor",Forecast_Lines!$U$4:$U$377,"Yes",Forecast_Lines!$O$4:$O$377,E$4) -> 36456 | F12: =SUMIFS(Forecast_Lines!$J$4:$J$377,Forecast_Lines!$D$4:$D$377,"Receipt",Forecast_Lines!$E$4:$E$377,"Customer – Furniture distributor",Forecast_Lines!$U$4:$U$377,"Yes",Forecast_Lines!$O$4:$O$377,F$4) -> 47616 | G12: =SUMIFS(Forecast_Lines!$J$4:$J$377,Forecast_Lines!$D$4:$D$377,"Receipt",Forecast_Lines!$E$4:$E$377,"Customer – Furniture distributor",Forecast_Lines!$U$4:$U$377,"Yes",Forecast_Lines!$O$4:$O$377,G$4) -> 47196 | H12: =SUMIFS(Forecast_Lines!$J$4:$J$377,Forecast_Lines!$D$4:$D$377,"Receipt",Forecast_Lines!$E$4:$E$377,"Customer – Furniture distributor",Forecast_Lines!$U$4:$U$377,"Yes",Forecast_Lines!$O$4:$O$377,H$4) -> 23904 | I12: =SUMIFS(Forecast_Lines!$J$4:$J$377,Forecast_Lines!$D$4:$D$377,"Receipt",Forecast_Lines!$E$4:$E$377,"Customer – Furniture distributor",Forecast_Lines!$U$4:$U$377,"Yes",Forecast_Lines!$O$4:$O$377,I$4) -> 27588 | J12: =SUMIFS(Forecast_Lines!$J$4:$J$377,Forecast_Lines!$D$4:$D$377,"Receipt",Forecast_Lines!$E$4:$E$377,"Customer – Furniture distributor",Forecast_Lines!$U$4:$U$377,"Yes",Forecast_Lines!$O$4:$O$377,J$4) -> 42696 | ... O12: =SUMIFS(Forecast_Lines!$J$4:$J$377,Forecast_Lines!$D$4:$D$377,"Receipt",Forecast_Lines!$E$4:$E$377,"Customer – Furniture distributor",Forecast_Lines!$U$4:$U$377,"Yes",Forecast_Lines!$O$4:$O$377,O$4) -> 36216 | P12: =SUM(C12:O12) -> 508128
A13: Public sector | B13: SUMIFS on Forecast_Lines | C13: =SUMIFS(Forecast_Lines!$J$4:$J$377,Forecast_Lines!$D$4:$D$377,"Receipt",Forecast_Lines!$E$4:$E$377,"Customer – Public sector",Forecast_Lines!$U$4:$U$377,"Yes",Forecast_Lines!$O$4:$O$377,C$4) -> 0 | D13: =SUMIFS(Forecast_Lines!$J$4:$J$377,Forecast_Lines!$D$4:$D$377,"Receipt",Forecast_Lines!$E$4:$E$377,"Customer – Public sector",Forecast_Lines!$U$4:$U$377,"Yes",Forecast_Lines!$O$4:$O$377,D$4) -> 0 | E13: =SUMIFS(Forecast_Lines!$J$4:$J$377,Forecast_Lines!$D$4:$D$377,"Receipt",Forecast_Lines!$E$4:$E$377,"Customer – Public sector",Forecast_Lines!$U$4:$U$377,"Yes",Forecast_Lines!$O$4:$O$377,E$4) -> 14520 | F13: =SUMIFS(Forecast_Lines!$J$4:$J$377,Forecast_Lines!$D$4:$D$377,"Receipt",Forecast_Lines!$E$4:$E$377,"Customer – Public sector",Forecast_Lines!$U$4:$U$377,"Yes",Forecast_Lines!$O$4:$O$377,F$4) -> 29448 | G13: =SUMIFS(Forecast_Lines!$J$4:$J$377,Forecast_Lines!$D$4:$D$377,"Receipt",Forecast_Lines!$E$4:$E$377,"Customer – Public sector",Forecast_Lines!$U$4:$U$377,"Yes",Forecast_Lines!$O$4:$O$377,G$4) -> 0 | H13: =SUMIFS(Forecast_Lines!$J$4:$J$377,Forecast_Lines!$D$4:$D$377,"Receipt",Forecast_Lines!$E$4:$E$377,"Customer – Public sector",Forecast_Lines!$U$4:$U$377,"Yes",Forecast_Lines!$O$4:$O$377,H$4) -> 37440 | I13: =SUMIFS(Forecast_Lines!$J$4:$J$377,Forecast_Lines!$D$4:$D$377,"Receipt",Forecast_Lines!$E$4:$E$377,"Customer – Public sector",Forecast_Lines!$U$4:$U$377,"Yes",Forecast_Lines!$O$4:$O$377,I$4) -> 0 | J13: =SUMIFS(Forecast_Lines!$J$4:$J$377,Forecast_Lines!$D$4:$D$377,"Receipt",Forecast_Lines!$E$4:$E$377,"Customer – Public sector",Forecast_Lines!$U$4:$U$377,"Yes",Forecast_Lines!$O$4:$O$377,J$4) -> 8436 | ... O13: =SUMIFS(Forecast_Lines!$J$4:$J$377,Forecast_Lines!$D$4:$D$377,"Receipt",Forecast_Lines!$E$4:$E$377,"Customer – Public sector",Forecast_Lines!$U$4:$U$377,"Yes",Forecast_Lines!$O$4:$O$377,O$4) -> 17472 | P13: =SUM(C13:O13) -> 131364
A14: Public sector (hospital) | B14: SUMIFS on Forecast_Lines | C14: =SUMIFS(Forecast_Lines!$J$4:$J$377,Forecast_Lines!$D$4:$D$377,"Receipt",Forecast_Lines!$E$4:$E$377,"Customer – Public sector (hospital)",Forecast_Lines!$U$4:$U$377,"Yes",Forecast_Lines!$O$4:$O$377,C$4) -> 0 | D14: =SUMIFS(Forecast_Lines!$J$4:$J$377,Forecast_Lines!$D$4:$D$377,"Receipt",Forecast_Lines!$E$4:$E$377,"Customer – Public sector (hospital)",Forecast_Lines!$U$4:$U$377,"Yes",Forecast_Lines!$O$4:$O$377,D$4) -> 0 | E14: =SUMIFS(Forecast_Lines!$J$4:$J$377,Forecast_Lines!$D$4:$D$377,"Receipt",Forecast_Lines!$E$4:$E$377,"Customer – Public sector (hospital)",Forecast_Lines!$U$4:$U$377,"Yes",Forecast_Lines!$O$4:$O$377,E$4) -> 0 | F14: =SUMIFS(Forecast_Lines!$J$4:$J$377,Forecast_Lines!$D$4:$D$377,"Receipt",Forecast_Lines!$E$4:$E$377,"Customer – Public sector (hospital)",Forecast_Lines!$U$4:$U$377,"Yes",Forecast_Lines!$O$4:$O$377,F$4) -> 0 | G14: =SUMIFS(Forecast_Lines!$J$4:$J$377,Forecast_Lines!$D$4:$D$377,"Receipt",Forecast_Lines!$E$4:$E$377,"Customer – Public sector (hospital)",Forecast_Lines!$U$4:$U$377,"Yes",Forecast_Lines!$O$4:$O$377,G$4) -> 0 | H14: =SUMIFS(Forecast_Lines!$J$4:$J$377,Forecast_Lines!$D$4:$D$377,"Receipt",Forecast_Lines!$E$4:$E$377,"Customer – Public sector (hospital)",Forecast_Lines!$U$4:$U$377,"Yes",Forecast_Lines!$O$4:$O$377,H$4) -> 0 | I14: =SUMIFS(Forecast_Lines!$J$4:$J$377,Forecast_Lines!$D$4:$D$377,"Receipt",Forecast_Lines!$E$4:$E$377,"Customer – Public sector (hospital)",Forecast_Lines!$U$4:$U$377,"Yes",Forecast_Lines!$O$4:$O$377,I$4) -> 35172 | J14: =SUMIFS(Forecast_Lines!$J$4:$J$377,Forecast_Lines!$D$4:$D$377,"Receipt",Forecast_Lines!$E$4:$E$377,"Customer – Public sector (hospital)",Forecast_Lines!$U$4:$U$377,"Yes",Forecast_Lines!$O$4:$O$377,J$4) -> 0 | ... O14: =SUMIFS(Forecast_Lines!$J$4:$J$377,Forecast_Lines!$D$4:$D$377,"Receipt",Forecast_Lines!$E$4:$E$377,"Customer – Public sector (hospital)",Forecast_Lines!$U$4:$U$377,"Yes",Forecast_Lines!$O$4:$O$377,O$4) -> 31236 | P14: =SUM(C14:O14) -> 71880
A15: Hospitality (projects) | B15: SUMIFS on Forecast_Lines | C15: =SUMIFS(Forecast_Lines!$J$4:$J$377,Forecast_Lines!$D$4:$D$377,"Receipt",Forecast_Lines!$E$4:$E$377,"Customer – Hospitality (projects)",Forecast_Lines!$U$4:$U$377,"Yes",Forecast_Lines!$O$4:$O$377,C$4) -> 0 | D15: =SUMIFS(Forecast_Lines!$J$4:$J$377,Forecast_Lines!$D$4:$D$377,"Receipt",Forecast_Lines!$E$4:$E$377,"Customer – Hospitality (projects)",Forecast_Lines!$U$4:$U$377,"Yes",Forecast_Lines!$O$4:$O$377,D$4) -> 0 | E15: =SUMIFS(Forecast_Lines!$J$4:$J$377,Forecast_Lines!$D$4:$D$377,"Receipt",Forecast_Lines!$E$4:$E$377,"Customer – Hospitality (projects)",Forecast_Lines!$U$4:$U$377,"Yes",Forecast_Lines!$O$4:$O$377,E$4) -> 0 | F15: =SUMIFS(Forecast_Lines!$J$4:$J$377,Forecast_Lines!$D$4:$D$377,"Receipt",Forecast_Lines!$E$4:$E$377,"Customer – Hospitality (projects)",Forecast_Lines!$U$4:$U$377,"Yes",Forecast_Lines!$O$4:$O$377,F$4) -> 0 | G15: =SUMIFS(Forecast_Lines!$J$4:$J$377,Forecast_Lines!$D$4:$D$377,"Receipt",Forecast_Lines!$E$4:$E$377,"Customer – Hospitality (projects)",Forecast_Lines!$U$4:$U$377,"Yes",Forecast_Lines!$O$4:$O$377,G$4) -> 0 | H15: =SUMIFS(Forecast_Lines!$J$4:$J$377,Forecast_Lines!$D$4:$D$377,"Receipt",Forecast_Lines!$E$4:$E$377,"Customer – Hospitality (projects)",Forecast_Lines!$U$4:$U$377,"Yes",Forecast_Lines!$O$4:$O$377,H$4) -> 0 | I15: =SUMIFS(Forecast_Lines!$J$4:$J$377,Forecast_Lines!$D$4:$D$377,"Receipt",Forecast_Lines!$E$4:$E$377,"Customer – Hospitality (projects)",Forecast_Lines!$U$4:$U$377,"Yes",Forecast_Lines!$O$4:$O$377,I$4) -> 230400 | J15: =SUMIFS(Forecast_Lines!$J$4:$J$377,Forecast_Lines!$D$4:$D$377,"Receipt",Forecast_Lines!$E$4:$E$377,"Customer – Hospitality (projects)",Forecast_Lines!$U$4:$U$377,"Yes",Forecast_Lines!$O$4:$O$377,J$4) -> 0 | ... O15: =SUMIFS(Forecast_Lines!$J$4:$J$377,Forecast_Lines!$D$4:$D$377,"Receipt",Forecast_Lines!$E$4:$E$377,"Customer – Hospitality (projects)",Forecast_Lines!$U$4:$U$377,"Yes",Forecast_Lines!$O$4:$O$377,O$4) -> 0 | P15: =SUM(C15:O15) -> 360000
A16: Export distributor | B16: SUMIFS on Forecast_Lines | C16: =SUMIFS(Forecast_Lines!$J$4:$J$377,Forecast_Lines!$D$4:$D$377,"Receipt",Forecast_Lines!$E$4:$E$377,"Customer – Export distributor",Forecast_Lines!$U$4:$U$377,"Yes",Forecast_Lines!$O$4:$O$377,C$4) -> 21030 | D16: =SUMIFS(Forecast_Lines!$J$4:$J$377,Forecast_Lines!$D$4:$D$377,"Receipt",Forecast_Lines!$E$4:$E$377,"Customer – Export distributor",Forecast_Lines!$U$4:$U$377,"Yes",Forecast_Lines!$O$4:$O$377,D$4) -> 0 | E16: =SUMIFS(Forecast_Lines!$J$4:$J$377,Forecast_Lines!$D$4:$D$377,"Receipt",Forecast_Lines!$E$4:$E$377,"Customer – Export distributor",Forecast_Lines!$U$4:$U$377,"Yes",Forecast_Lines!$O$4:$O$377,E$4) -> 0 | F16: =SUMIFS(Forecast_Lines!$J$4:$J$377,Forecast_Lines!$D$4:$D$377,"Receipt",Forecast_Lines!$E$4:$E$377,"Customer – Export distributor",Forecast_Lines!$U$4:$U$377,"Yes",Forecast_Lines!$O$4:$O$377,F$4) -> 0 | G16: =SUMIFS(Forecast_Lines!$J$4:$J$377,Forecast_Lines!$D$4:$D$377,"Receipt",Forecast_Lines!$E$4:$E$377,"Customer – Export distributor",Forecast_Lines!$U$4:$U$377,"Yes",Forecast_Lines!$O$4:$O$377,G$4) -> 13160 | H16: =SUMIFS(Forecast_Lines!$J$4:$J$377,Forecast_Lines!$D$4:$D$377,"Receipt",Forecast_Lines!$E$4:$E$377,"Customer – Export distributor",Forecast_Lines!$U$4:$U$377,"Yes",Forecast_Lines!$O$4:$O$377,H$4) -> 13020 | I16: =SUMIFS(Forecast_Lines!$J$4:$J$377,Forecast_Lines!$D$4:$D$377,"Receipt",Forecast_Lines!$E$4:$E$377,"Customer – Export distributor",Forecast_Lines!$U$4:$U$377,"Yes",Forecast_Lines!$O$4:$O$377,I$4) -> 6820 | J16: =SUMIFS(Forecast_Lines!$J$4:$J$377,Forecast_Lines!$D$4:$D$377,"Receipt",Forecast_Lines!$E$4:$E$377,"Customer – Export distributor",Forecast_Lines!$U$4:$U$377,"Yes",Forecast_Lines!$O$4:$O$377,J$4) -> 10970 | ... O16: =SUMIFS(Forecast_Lines!$J$4:$J$377,Forecast_Lines!$D$4:$D$377,"Receipt",Forecast_Lines!$E$4:$E$377,"Customer – Export distributor",Forecast_Lines!$U$4:$U$377,"Yes",Forecast_Lines!$O$4:$O$377,O$4) -> 15980 | P16: =SUM(C16:O16) -> 126860
A17: Direct corporate client | B17: SUMIFS on Forecast_Lines | C17: =SUMIFS(Forecast_Lines!$J$4:$J$377,Forecast_Lines!$D$4:$D$377,"Receipt",Forecast_Lines!$E$4:$E$377,"Customer – Direct corporate client",Forecast_Lines!$U$4:$U$377,"Yes",Forecast_Lines!$O$4:$O$377,C$4) -> 2808 | D17: =SUMIFS(Forecast_Lines!$J$4:$J$377,Forecast_Lines!$D$4:$D$377,"Receipt",Forecast_Lines!$E$4:$E$377,"Customer – Direct corporate client",Forecast_Lines!$U$4:$U$377,"Yes",Forecast_Lines!$O$4:$O$377,D$4) -> 22092 | E17: =SUMIFS(Forecast_Lines!$J$4:$J$377,Forecast_Lines!$D$4:$D$377,"Receipt",Forecast_Lines!$E$4:$E$377,"Customer – Direct corporate client",Forecast_Lines!$U$4:$U$377,"Yes",Forecast_Lines!$O$4:$O$377,E$4) -> 11508 | F17: =SUMIFS(Forecast_Lines!$J$4:$J$377,Forecast_Lines!$D$4:$D$377,"Receipt",Forecast_Lines!$E$4:$E$377,"Customer – Direct corporate client",Forecast_Lines!$U$4:$U$377,"Yes",Forecast_Lines!$O$4:$O$377,F$4) -> 0 | G17: =SUMIFS(Forecast_Lines!$J$4:$J$377,Forecast_Lines!$D$4:$D$377,"Receipt",Forecast_Lines!$E$4:$E$377,"Customer – Direct corporate client",Forecast_Lines!$U$4:$U$377,"Yes",Forecast_Lines!$O$4:$O$377,G$4) -> 8004 | H17: =SUMIFS(Forecast_Lines!$J$4:$J$377,Forecast_Lines!$D$4:$D$377,"Receipt",Forecast_Lines!$E$4:$E$377,"Customer – Direct corporate client",Forecast_Lines!$U$4:$U$377,"Yes",Forecast_Lines!$O$4:$O$377,H$4) -> 7680 | I17: =SUMIFS(Forecast_Lines!$J$4:$J$377,Forecast_Lines!$D$4:$D$377,"Receipt",Forecast_Lines!$E$4:$E$377,"Customer – Direct corporate client",Forecast_Lines!$U$4:$U$377,"Yes",Forecast_Lines!$O$4:$O$377,I$4) -> 13416 | J17: =SUMIFS(Forecast_Lines!$J$4:$J$377,Forecast_Lines!$D$4:$D$377,"Receipt",Forecast_Lines!$E$4:$E$377,"Customer – Direct corporate client",Forecast_Lines!$U$4:$U$377,"Yes",Forecast_Lines!$O$4:$O$377,J$4) -> 3804 | ... O17: =SUMIFS(Forecast_Lines!$J$4:$J$377,Forecast_Lines!$D$4:$D$377,"Receipt",Forecast_Lines!$E$4:$E$377,"Customer – Direct corporate client",Forecast_Lines!$U$4:$U$377,"Yes",Forecast_Lines!$O$4:$O$377,O$4) -> 3753.6 | P17: =SUM(C17:O17) -> 108885.6
A18: Total receipts | C18: =SUM(C11:C17) -> 43422 | D18: =SUM(D11:D17) -> 177048 | E18: =SUM(E11:E17) -> 90984 | F18: =SUM(F11:F17) -> 147432 | G18: =SUM(G11:G17) -> 112196 | H18: =SUM(H11:H17) -> 155832 | I18: =SUM(I11:I17) -> 391012 | J18: =SUM(J11:J17) -> 100634 | ... O18: =SUM(O11:O17) -> 187280 | P18: =SUM(C18:O18) -> 2186732
A19: Payments
A20: Supplier payment | B20: SUMIFS on Forecast_Lines | C20: =SUMIFS(Forecast_Lines!$J$4:$J$377,Forecast_Lines!$D$4:$D$377,"Payment",Forecast_Lines!$E$4:$E$377,"Supplier payment",Forecast_Lines!$O$4:$O$377,C$4) -> -47282.15 | D20: =SUMIFS(Forecast_Lines!$J$4:$J$377,Forecast_Lines!$D$4:$D$377,"Payment",Forecast_Lines!$E$4:$E$377,"Supplier payment",Forecast_Lines!$O$4:$O$377,D$4) -> -6011.58 | E20: =SUMIFS(Forecast_Lines!$J$4:$J$377,Forecast_Lines!$D$4:$D$377,"Payment",Forecast_Lines!$E$4:$E$377,"Supplier payment",Forecast_Lines!$O$4:$O$377,E$4) -> -218823.92 | F20: =SUMIFS(Forecast_Lines!$J$4:$J$377,Forecast_Lines!$D$4:$D$377,"Payment",Forecast_Lines!$E$4:$E$377,"Supplier payment",Forecast_Lines!$O$4:$O$377,F$4) -> -61018.47 | G20: =SUMIFS(Forecast_Lines!$J$4:$J$377,Forecast_Lines!$D$4:$D$377,"Payment",Forecast_Lines!$E$4:$E$377,"Supplier payment",Forecast_Lines!$O$4:$O$377,G$4) -> -6312.02 | H20: =SUMIFS(Forecast_Lines!$J$4:$J$377,Forecast_Lines!$D$4:$D$377,"Payment",Forecast_Lines!$E$4:$E$377,"Supplier payment",Forecast_Lines!$O$4:$O$377,H$4) -> -200469.89 | I20: =SUMIFS(Forecast_Lines!$J$4:$J$377,Forecast_Lines!$D$4:$D$377,"Payment",Forecast_Lines!$E$4:$E$377,"Supplier payment",Forecast_Lines!$O$4:$O$377,I$4) -> -24992.24 | J20: =SUMIFS(Forecast_Lines!$J$4:$J$377,Forecast_Lines!$D$4:$D$377,"Payment",Forecast_Lines!$E$4:$E$377,"Supplier payment",Forecast_Lines!$O$4:$O$377,J$4) -> -166105.32 | ... O20: =SUMIFS(Forecast_Lines!$J$4:$J$377,Forecast_Lines!$D$4:$D$377,"Payment",Forecast_Lines!$E$4:$E$377,"Supplier payment",Forecast_Lines!$O$4:$O$377,O$4) -> -50387.76 | P20: =SUM(C20:O20) -> -1079808
A21: Payroll | B21: SUMIFS on Forecast_Lines | C21: =SUMIFS(Forecast_Lines!$J$4:$J$377,Forecast_Lines!$D$4:$D$377,"Payment",Forecast_Lines!$E$4:$E$377,"Payroll",Forecast_Lines!$O$4:$O$377,C$4) -> 0 | D21: =SUMIFS(Forecast_Lines!$J$4:$J$377,Forecast_Lines!$D$4:$D$377,"Payment",Forecast_Lines!$E$4:$E$377,"Payroll",Forecast_Lines!$O$4:$O$377,D$4) -> 0 | E21: =SUMIFS(Forecast_Lines!$J$4:$J$377,Forecast_Lines!$D$4:$D$377,"Payment",Forecast_Lines!$E$4:$E$377,"Payroll",Forecast_Lines!$O$4:$O$377,E$4) -> -106000 | F21: =SUMIFS(Forecast_Lines!$J$4:$J$377,Forecast_Lines!$D$4:$D$377,"Payment",Forecast_Lines!$E$4:$E$377,"Payroll",Forecast_Lines!$O$4:$O$377,F$4) -> 0 | G21: =SUMIFS(Forecast_Lines!$J$4:$J$377,Forecast_Lines!$D$4:$D$377,"Payment",Forecast_Lines!$E$4:$E$377,"Payroll",Forecast_Lines!$O$4:$O$377,G$4) -> 0 | H21: =SUMIFS(Forecast_Lines!$J$4:$J$377,Forecast_Lines!$D$4:$D$377,"Payment",Forecast_Lines!$E$4:$E$377,"Payroll",Forecast_Lines!$O$4:$O$377,H$4) -> 0 | I21: =SUMIFS(Forecast_Lines!$J$4:$J$377,Forecast_Lines!$D$4:$D$377,"Payment",Forecast_Lines!$E$4:$E$377,"Payroll",Forecast_Lines!$O$4:$O$377,I$4) -> 0 | J21: =SUMIFS(Forecast_Lines!$J$4:$J$377,Forecast_Lines!$D$4:$D$377,"Payment",Forecast_Lines!$E$4:$E$377,"Payroll",Forecast_Lines!$O$4:$O$377,J$4) -> -106000 | ... O21: =SUMIFS(Forecast_Lines!$J$4:$J$377,Forecast_Lines!$D$4:$D$377,"Payment",Forecast_Lines!$E$4:$E$377,"Payroll",Forecast_Lines!$O$4:$O$377,O$4) -> 0 | P21: =SUM(C21:O21) -> -390000
A22: VAT payment | B22: SUMIFS on Forecast_Lines | C22: =SUMIFS(Forecast_Lines!$J$4:$J$377,Forecast_Lines!$D$4:$D$377,"Payment",Forecast_Lines!$E$4:$E$377,"VAT payment",Forecast_Lines!$O$4:$O$377,C$4) -> 0 | D22: =SUMIFS(Forecast_Lines!$J$4:$J$377,Forecast_Lines!$D$4:$D$377,"Payment",Forecast_Lines!$E$4:$E$377,"VAT payment",Forecast_Lines!$O$4:$O$377,D$4) -> 0 | E22: =SUMIFS(Forecast_Lines!$J$4:$J$377,Forecast_Lines!$D$4:$D$377,"Payment",Forecast_Lines!$E$4:$E$377,"VAT payment",Forecast_Lines!$O$4:$O$377,E$4) -> -109780 | F22: =SUMIFS(Forecast_Lines!$J$4:$J$377,Forecast_Lines!$D$4:$D$377,"Payment",Forecast_Lines!$E$4:$E$377,"VAT payment",Forecast_Lines!$O$4:$O$377,F$4) -> 0 | G22: =SUMIFS(Forecast_Lines!$J$4:$J$377,Forecast_Lines!$D$4:$D$377,"Payment",Forecast_Lines!$E$4:$E$377,"VAT payment",Forecast_Lines!$O$4:$O$377,G$4) -> 0 | H22: =SUMIFS(Forecast_Lines!$J$4:$J$377,Forecast_Lines!$D$4:$D$377,"Payment",Forecast_Lines!$E$4:$E$377,"VAT payment",Forecast_Lines!$O$4:$O$377,H$4) -> 0 | I22: =SUMIFS(Forecast_Lines!$J$4:$J$377,Forecast_Lines!$D$4:$D$377,"Payment",Forecast_Lines!$E$4:$E$377,"VAT payment",Forecast_Lines!$O$4:$O$377,I$4) -> -102020 | J22: =SUMIFS(Forecast_Lines!$J$4:$J$377,Forecast_Lines!$D$4:$D$377,"Payment",Forecast_Lines!$E$4:$E$377,"VAT payment",Forecast_Lines!$O$4:$O$377,J$4) -> 0 | ... O22: =SUMIFS(Forecast_Lines!$J$4:$J$377,Forecast_Lines!$D$4:$D$377,"Payment",Forecast_Lines!$E$4:$E$377,"VAT payment",Forecast_Lines!$O$4:$O$377,O$4) -> 0 | P22: =SUM(C22:O22) -> -301220
A23: Social charges & income tax withheld | B23: SUMIFS on Forecast_Lines | C23: =SUMIFS(Forecast_Lines!$J$4:$J$377,Forecast_Lines!$D$4:$D$377,"Payment",Forecast_Lines!$E$4:$E$377,"Social charges & income tax withheld",Forecast_Lines!$O$4:$O$377,C$4) -> -86000 | D23: =SUMIFS(Forecast_Lines!$J$4:$J$377,Forecast_Lines!$D$4:$D$377,"Payment",Forecast_Lines!$E$4:$E$377,"Social charges & income tax withheld",Forecast_Lines!$O$4:$O$377,D$4) -> 0 | E23: =SUMIFS(Forecast_Lines!$J$4:$J$377,Forecast_Lines!$D$4:$D$377,"Payment",Forecast_Lines!$E$4:$E$377,"Social charges & income tax withheld",Forecast_Lines!$O$4:$O$377,E$4) -> 0 | F23: =SUMIFS(Forecast_Lines!$J$4:$J$377,Forecast_Lines!$D$4:$D$377,"Payment",Forecast_Lines!$E$4:$E$377,"Social charges & income tax withheld",Forecast_Lines!$O$4:$O$377,F$4) -> 0 | G23: =SUMIFS(Forecast_Lines!$J$4:$J$377,Forecast_Lines!$D$4:$D$377,"Payment",Forecast_Lines!$E$4:$E$377,"Social charges & income tax withheld",Forecast_Lines!$O$4:$O$377,G$4) -> 0 | H23: =SUMIFS(Forecast_Lines!$J$4:$J$377,Forecast_Lines!$D$4:$D$377,"Payment",Forecast_Lines!$E$4:$E$377,"Social charges & income tax withheld",Forecast_Lines!$O$4:$O$377,H$4) -> -86000 | I23: =SUMIFS(Forecast_Lines!$J$4:$J$377,Forecast_Lines!$D$4:$D$377,"Payment",Forecast_Lines!$E$4:$E$377,"Social charges & income tax withheld",Forecast_Lines!$O$4:$O$377,I$4) -> 0 | J23: =SUMIFS(Forecast_Lines!$J$4:$J$377,Forecast_Lines!$D$4:$D$377,"Payment",Forecast_Lines!$E$4:$E$377,"Social charges & income tax withheld",Forecast_Lines!$O$4:$O$377,J$4) -> 0 | ... O23: =SUMIFS(Forecast_Lines!$J$4:$J$377,Forecast_Lines!$D$4:$D$377,"Payment",Forecast_Lines!$E$4:$E$377,"Social charges & income tax withheld",Forecast_Lines!$O$4:$O$377,O$4) -> 0 | P23: =SUM(C23:O23) -> -258000
A24: Card & sundry spending | B24: SUMIFS on Forecast_Lines | C24: =SUMIFS(Forecast_Lines!$J$4:$J$377,Forecast_Lines!$D$4:$D$377,"Payment",Forecast_Lines!$E$4:$E$377,"Card & sundry spending",Forecast_Lines!$O$4:$O$377,C$4) -> -4700 | D24: =SUMIFS(Forecast_Lines!$J$4:$J$377,Forecast_Lines!$D$4:$D$377,"Payment",Forecast_Lines!$E$4:$E$377,"Card & sundry spending",Forecast_Lines!$O$4:$O$377,D$4) -> -4700 | E24: =SUMIFS(Forecast_Lines!$J$4:$J$377,Forecast_Lines!$D$4:$D$377,"Payment",Forecast_Lines!$E$4:$E$377,"Card & sundry spending",Forecast_Lines!$O$4:$O$377,E$4) -> -4700 | F24: =SUMIFS(Forecast_Lines!$J$4:$J$377,Forecast_Lines!$D$4:$D$377,"Payment",Forecast_Lines!$E$4:$E$377,"Card & sundry spending",Forecast_Lines!$O$4:$O$377,F$4) -> -4700 | G24: =SUMIFS(Forecast_Lines!$J$4:$J$377,Forecast_Lines!$D$4:$D$377,"Payment",Forecast_Lines!$E$4:$E$377,"Card & sundry spending",Forecast_Lines!$O$4:$O$377,G$4) -> -4700 | H24: =SUMIFS(Forecast_Lines!$J$4:$J$377,Forecast_Lines!$D$4:$D$377,"Payment",Forecast_Lines!$E$4:$E$377,"Card & sundry spending",Forecast_Lines!$O$4:$O$377,H$4) -> -4700 | I24: =SUMIFS(Forecast_Lines!$J$4:$J$377,Forecast_Lines!$D$4:$D$377,"Payment",Forecast_Lines!$E$4:$E$377,"Card & sundry spending",Forecast_Lines!$O$4:$O$377,I$4) -> -4700 | J24: =SUMIFS(Forecast_Lines!$J$4:$J$377,Forecast_Lines!$D$4:$D$377,"Payment",Forecast_Lines!$E$4:$E$377,"Card & sundry spending",Forecast_Lines!$O$4:$O$377,J$4) -> -4700 | ... O24: =SUMIFS(Forecast_Lines!$J$4:$J$377,Forecast_Lines!$D$4:$D$377,"Payment",Forecast_Lines!$E$4:$E$377,"Card & sundry spending",Forecast_Lines!$O$4:$O$377,O$4) -> -4700 | P24: =SUM(C24:O24) -> -58200
A25: Energy | B25: SUMIFS on Forecast_Lines | C25: =SUMIFS(Forecast_Lines!$J$4:$J$377,Forecast_Lines!$D$4:$D$377,"Payment",Forecast_Lines!$E$4:$E$377,"Energy",Forecast_Lines!$O$4:$O$377,C$4) -> 0 | D25: =SUMIFS(Forecast_Lines!$J$4:$J$377,Forecast_Lines!$D$4:$D$377,"Payment",Forecast_Lines!$E$4:$E$377,"Energy",Forecast_Lines!$O$4:$O$377,D$4) -> 0 | E25: =SUMIFS(Forecast_Lines!$J$4:$J$377,Forecast_Lines!$D$4:$D$377,"Payment",Forecast_Lines!$E$4:$E$377,"Energy",Forecast_Lines!$O$4:$O$377,E$4) -> 0 | F25: =SUMIFS(Forecast_Lines!$J$4:$J$377,Forecast_Lines!$D$4:$D$377,"Payment",Forecast_Lines!$E$4:$E$377,"Energy",Forecast_Lines!$O$4:$O$377,F$4) -> 0 | G25: =SUMIFS(Forecast_Lines!$J$4:$J$377,Forecast_Lines!$D$4:$D$377,"Payment",Forecast_Lines!$E$4:$E$377,"Energy",Forecast_Lines!$O$4:$O$377,G$4) -> -14160 | H25: =SUMIFS(Forecast_Lines!$J$4:$J$377,Forecast_Lines!$D$4:$D$377,"Payment",Forecast_Lines!$E$4:$E$377,"Energy",Forecast_Lines!$O$4:$O$377,H$4) -> 0 | I25: =SUMIFS(Forecast_Lines!$J$4:$J$377,Forecast_Lines!$D$4:$D$377,"Payment",Forecast_Lines!$E$4:$E$377,"Energy",Forecast_Lines!$O$4:$O$377,I$4) -> 0 | J25: =SUMIFS(Forecast_Lines!$J$4:$J$377,Forecast_Lines!$D$4:$D$377,"Payment",Forecast_Lines!$E$4:$E$377,"Energy",Forecast_Lines!$O$4:$O$377,J$4) -> 0 | ... O25: =SUMIFS(Forecast_Lines!$J$4:$J$377,Forecast_Lines!$D$4:$D$377,"Payment",Forecast_Lines!$E$4:$E$377,"Energy",Forecast_Lines!$O$4:$O$377,O$4) -> -14160 | P25: =SUM(C25:O25) -> -42480
A26: Capex (discretionary) | B26: SUMIFS on Forecast_Lines | C26: =SUMIFS(Forecast_Lines!$J$4:$J$377,Forecast_Lines!$D$4:$D$377,"Payment",Forecast_Lines!$E$4:$E$377,"Capex (discretionary)",Forecast_Lines!$O$4:$O$377,C$4) -> 0 | D26: =SUMIFS(Forecast_Lines!$J$4:$J$377,Forecast_Lines!$D$4:$D$377,"Payment",Forecast_Lines!$E$4:$E$377,"Capex (discretionary)",Forecast_Lines!$O$4:$O$377,D$4) -> 0 | E26: =SUMIFS(Forecast_Lines!$J$4:$J$377,Forecast_Lines!$D$4:$D$377,"Payment",Forecast_Lines!$E$4:$E$377,"Capex (discretionary)",Forecast_Lines!$O$4:$O$377,E$4) -> 0 | F26: =SUMIFS(Forecast_Lines!$J$4:$J$377,Forecast_Lines!$D$4:$D$377,"Payment",Forecast_Lines!$E$4:$E$377,"Capex (discretionary)",Forecast_Lines!$O$4:$O$377,F$4) -> 0 | G26: =SUMIFS(Forecast_Lines!$J$4:$J$377,Forecast_Lines!$D$4:$D$377,"Payment",Forecast_Lines!$E$4:$E$377,"Capex (discretionary)",Forecast_Lines!$O$4:$O$377,G$4) -> 0 | H26: =SUMIFS(Forecast_Lines!$J$4:$J$377,Forecast_Lines!$D$4:$D$377,"Payment",Forecast_Lines!$E$4:$E$377,"Capex (discretionary)",Forecast_Lines!$O$4:$O$377,H$4) -> 0 | I26: =SUMIFS(Forecast_Lines!$J$4:$J$377,Forecast_Lines!$D$4:$D$377,"Payment",Forecast_Lines!$E$4:$E$377,"Capex (discretionary)",Forecast_Lines!$O$4:$O$377,I$4) -> -34560 | J26: =SUMIFS(Forecast_Lines!$J$4:$J$377,Forecast_Lines!$D$4:$D$377,"Payment",Forecast_Lines!$E$4:$E$377,"Capex (discretionary)",Forecast_Lines!$O$4:$O$377,J$4) -> 0 | ... O26: =SUMIFS(Forecast_Lines!$J$4:$J$377,Forecast_Lines!$D$4:$D$377,"Payment",Forecast_Lines!$E$4:$E$377,"Capex (discretionary)",Forecast_Lines!$O$4:$O$377,O$4) -> 0 | P26: =SUM(C26:O26) -> -34560
A27: Bank loan repayment | B27: SUMIFS on Forecast_Lines | C27: =SUMIFS(Forecast_Lines!$J$4:$J$377,Forecast_Lines!$D$4:$D$377,"Payment",Forecast_Lines!$E$4:$E$377,"Bank loan repayment",Forecast_Lines!$O$4:$O$377,C$4) -> 0 | D27: =SUMIFS(Forecast_Lines!$J$4:$J$377,Forecast_Lines!$D$4:$D$377,"Payment",Forecast_Lines!$E$4:$E$377,"Bank loan repayment",Forecast_Lines!$O$4:$O$377,D$4) -> 0 | E27: =SUMIFS(Forecast_Lines!$J$4:$J$377,Forecast_Lines!$D$4:$D$377,"Payment",Forecast_Lines!$E$4:$E$377,"Bank loan repayment",Forecast_Lines!$O$4:$O$377,E$4) -> 0 | F27: =SUMIFS(Forecast_Lines!$J$4:$J$377,Forecast_Lines!$D$4:$D$377,"Payment",Forecast_Lines!$E$4:$E$377,"Bank loan repayment",Forecast_Lines!$O$4:$O$377,F$4) -> -8900 | G27: =SUMIFS(Forecast_Lines!$J$4:$J$377,Forecast_Lines!$D$4:$D$377,"Payment",Forecast_Lines!$E$4:$E$377,"Bank loan repayment",Forecast_Lines!$O$4:$O$377,G$4) -> 0 | H27: =SUMIFS(Forecast_Lines!$J$4:$J$377,Forecast_Lines!$D$4:$D$377,"Payment",Forecast_Lines!$E$4:$E$377,"Bank loan repayment",Forecast_Lines!$O$4:$O$377,H$4) -> 0 | I27: =SUMIFS(Forecast_Lines!$J$4:$J$377,Forecast_Lines!$D$4:$D$377,"Payment",Forecast_Lines!$E$4:$E$377,"Bank loan repayment",Forecast_Lines!$O$4:$O$377,I$4) -> 0 | J27: =SUMIFS(Forecast_Lines!$J$4:$J$377,Forecast_Lines!$D$4:$D$377,"Payment",Forecast_Lines!$E$4:$E$377,"Bank loan repayment",Forecast_Lines!$O$4:$O$377,J$4) -> 0 | ... O27: =SUMIFS(Forecast_Lines!$J$4:$J$377,Forecast_Lines!$D$4:$D$377,"Payment",Forecast_Lines!$E$4:$E$377,"Bank loan repayment",Forecast_Lines!$O$4:$O$377,O$4) -> -8900 | P27: =SUM(C27:O27) -> -26700
A28: Corporate income tax instalment | B28: SUMIFS on Forecast_Lines | C28: =SUMIFS(Forecast_Lines!$J$4:$J$377,Forecast_Lines!$D$4:$D$377,"Payment",Forecast_Lines!$E$4:$E$377,"Corporate income tax instalment",Forecast_Lines!$O$4:$O$377,C$4) -> 0 | D28: =SUMIFS(Forecast_Lines!$J$4:$J$377,Forecast_Lines!$D$4:$D$377,"Payment",Forecast_Lines!$E$4:$E$377,"Corporate income tax instalment",Forecast_Lines!$O$4:$O$377,D$4) -> 0 | E28: =SUMIFS(Forecast_Lines!$J$4:$J$377,Forecast_Lines!$D$4:$D$377,"Payment",Forecast_Lines!$E$4:$E$377,"Corporate income tax instalment",Forecast_Lines!$O$4:$O$377,E$4) -> 0 | F28: =SUMIFS(Forecast_Lines!$J$4:$J$377,Forecast_Lines!$D$4:$D$377,"Payment",Forecast_Lines!$E$4:$E$377,"Corporate income tax instalment",Forecast_Lines!$O$4:$O$377,F$4) -> 0 | G28: =SUMIFS(Forecast_Lines!$J$4:$J$377,Forecast_Lines!$D$4:$D$377,"Payment",Forecast_Lines!$E$4:$E$377,"Corporate income tax instalment",Forecast_Lines!$O$4:$O$377,G$4) -> 0 | H28: =SUMIFS(Forecast_Lines!$J$4:$J$377,Forecast_Lines!$D$4:$D$377,"Payment",Forecast_Lines!$E$4:$E$377,"Corporate income tax instalment",Forecast_Lines!$O$4:$O$377,H$4) -> 0 | I28: =SUMIFS(Forecast_Lines!$J$4:$J$377,Forecast_Lines!$D$4:$D$377,"Payment",Forecast_Lines!$E$4:$E$377,"Corporate income tax instalment",Forecast_Lines!$O$4:$O$377,I$4) -> 0 | J28: =SUMIFS(Forecast_Lines!$J$4:$J$377,Forecast_Lines!$D$4:$D$377,"Payment",Forecast_Lines!$E$4:$E$377,"Corporate income tax instalment",Forecast_Lines!$O$4:$O$377,J$4) -> 0 | ... O28: =SUMIFS(Forecast_Lines!$J$4:$J$377,Forecast_Lines!$D$4:$D$377,"Payment",Forecast_Lines!$E$4:$E$377,"Corporate income tax instalment",Forecast_Lines!$O$4:$O$377,O$4) -> 0 | P28: =SUM(C28:O28) -> -24500
A29: Rent | B29: SUMIFS on Forecast_Lines | C29: =SUMIFS(Forecast_Lines!$J$4:$J$377,Forecast_Lines!$D$4:$D$377,"Payment",Forecast_Lines!$E$4:$E$377,"Rent",Forecast_Lines!$O$4:$O$377,C$4) -> 0 | D29: =SUMIFS(Forecast_Lines!$J$4:$J$377,Forecast_Lines!$D$4:$D$377,"Payment",Forecast_Lines!$E$4:$E$377,"Rent",Forecast_Lines!$O$4:$O$377,D$4) -> 0 | E29: =SUMIFS(Forecast_Lines!$J$4:$J$377,Forecast_Lines!$D$4:$D$377,"Payment",Forecast_Lines!$E$4:$E$377,"Rent",Forecast_Lines!$O$4:$O$377,E$4) -> 0 | F29: =SUMIFS(Forecast_Lines!$J$4:$J$377,Forecast_Lines!$D$4:$D$377,"Payment",Forecast_Lines!$E$4:$E$377,"Rent",Forecast_Lines!$O$4:$O$377,F$4) -> 0 | G29: =SUMIFS(Forecast_Lines!$J$4:$J$377,Forecast_Lines!$D$4:$D$377,"Payment",Forecast_Lines!$E$4:$E$377,"Rent",Forecast_Lines!$O$4:$O$377,G$4) -> 0 | H29: =SUMIFS(Forecast_Lines!$J$4:$J$377,Forecast_Lines!$D$4:$D$377,"Payment",Forecast_Lines!$E$4:$E$377,"Rent",Forecast_Lines!$O$4:$O$377,H$4) -> 0 | I29: =SUMIFS(Forecast_Lines!$J$4:$J$377,Forecast_Lines!$D$4:$D$377,"Payment",Forecast_Lines!$E$4:$E$377,"Rent",Forecast_Lines!$O$4:$O$377,I$4) -> 0 | J29: =SUMIFS(Forecast_Lines!$J$4:$J$377,Forecast_Lines!$D$4:$D$377,"Payment",Forecast_Lines!$E$4:$E$377,"Rent",Forecast_Lines!$O$4:$O$377,J$4) -> 0 | ... O29: =SUMIFS(Forecast_Lines!$J$4:$J$377,Forecast_Lines!$D$4:$D$377,"Payment",Forecast_Lines!$E$4:$E$377,"Rent",Forecast_Lines!$O$4:$O$377,O$4) -> -23400 | P29: =SUM(C29:O29) -> -23400
A30: Equipment lease | B30: SUMIFS on Forecast_Lines | C30: =SUMIFS(Forecast_Lines!$J$4:$J$377,Forecast_Lines!$D$4:$D$377,"Payment",Forecast_Lines!$E$4:$E$377,"Equipment lease",Forecast_Lines!$O$4:$O$377,C$4) -> -3840 | D30: =SUMIFS(Forecast_Lines!$J$4:$J$377,Forecast_Lines!$D$4:$D$377,"Payment",Forecast_Lines!$E$4:$E$377,"Equipment lease",Forecast_Lines!$O$4:$O$377,D$4) -> 0 | E30: =SUMIFS(Forecast_Lines!$J$4:$J$377,Forecast_Lines!$D$4:$D$377,"Payment",Forecast_Lines!$E$4:$E$377,"Equipment lease",Forecast_Lines!$O$4:$O$377,E$4) -> 0 | F30: =SUMIFS(Forecast_Lines!$J$4:$J$377,Forecast_Lines!$D$4:$D$377,"Payment",Forecast_Lines!$E$4:$E$377,"Equipment lease",Forecast_Lines!$O$4:$O$377,F$4) -> 0 | G30: =SUMIFS(Forecast_Lines!$J$4:$J$377,Forecast_Lines!$D$4:$D$377,"Payment",Forecast_Lines!$E$4:$E$377,"Equipment lease",Forecast_Lines!$O$4:$O$377,G$4) -> -3840 | H30: =SUMIFS(Forecast_Lines!$J$4:$J$377,Forecast_Lines!$D$4:$D$377,"Payment",Forecast_Lines!$E$4:$E$377,"Equipment lease",Forecast_Lines!$O$4:$O$377,H$4) -> 0 | I30: =SUMIFS(Forecast_Lines!$J$4:$J$377,Forecast_Lines!$D$4:$D$377,"Payment",Forecast_Lines!$E$4:$E$377,"Equipment lease",Forecast_Lines!$O$4:$O$377,I$4) -> 0 | J30: =SUMIFS(Forecast_Lines!$J$4:$J$377,Forecast_Lines!$D$4:$D$377,"Payment",Forecast_Lines!$E$4:$E$377,"Equipment lease",Forecast_Lines!$O$4:$O$377,J$4) -> 0 | ... O30: =SUMIFS(Forecast_Lines!$J$4:$J$377,Forecast_Lines!$D$4:$D$377,"Payment",Forecast_Lines!$E$4:$E$377,"Equipment lease",Forecast_Lines!$O$4:$O$377,O$4) -> 0 | P30: =SUM(C30:O30) -> -11520
A31: IT, telecom & software | B31: SUMIFS on Forecast_Lines | C31: =SUMIFS(Forecast_Lines!$J$4:$J$377,Forecast_Lines!$D$4:$D$377,"Payment",Forecast_Lines!$E$4:$E$377,"IT, telecom & software",Forecast_Lines!$O$4:$O$377,C$4) -> 0 | D31: =SUMIFS(Forecast_Lines!$J$4:$J$377,Forecast_Lines!$D$4:$D$377,"Payment",Forecast_Lines!$E$4:$E$377,"IT, telecom & software",Forecast_Lines!$O$4:$O$377,D$4) -> 0 | E31: =SUMIFS(Forecast_Lines!$J$4:$J$377,Forecast_Lines!$D$4:$D$377,"Payment",Forecast_Lines!$E$4:$E$377,"IT, telecom & software",Forecast_Lines!$O$4:$O$377,E$4) -> 0 | F31: =SUMIFS(Forecast_Lines!$J$4:$J$377,Forecast_Lines!$D$4:$D$377,"Payment",Forecast_Lines!$E$4:$E$377,"IT, telecom & software",Forecast_Lines!$O$4:$O$377,F$4) -> -2880 | G31: =SUMIFS(Forecast_Lines!$J$4:$J$377,Forecast_Lines!$D$4:$D$377,"Payment",Forecast_Lines!$E$4:$E$377,"IT, telecom & software",Forecast_Lines!$O$4:$O$377,G$4) -> 0 | H31: =SUMIFS(Forecast_Lines!$J$4:$J$377,Forecast_Lines!$D$4:$D$377,"Payment",Forecast_Lines!$E$4:$E$377,"IT, telecom & software",Forecast_Lines!$O$4:$O$377,H$4) -> 0 | I31: =SUMIFS(Forecast_Lines!$J$4:$J$377,Forecast_Lines!$D$4:$D$377,"Payment",Forecast_Lines!$E$4:$E$377,"IT, telecom & software",Forecast_Lines!$O$4:$O$377,I$4) -> 0 | J31: =SUMIFS(Forecast_Lines!$J$4:$J$377,Forecast_Lines!$D$4:$D$377,"Payment",Forecast_Lines!$E$4:$E$377,"IT, telecom & software",Forecast_Lines!$O$4:$O$377,J$4) -> -2880 | ... O31: =SUMIFS(Forecast_Lines!$J$4:$J$377,Forecast_Lines!$D$4:$D$377,"Payment",Forecast_Lines!$E$4:$E$377,"IT, telecom & software",Forecast_Lines!$O$4:$O$377,O$4) -> -2880 | P31: =SUM(C31:O31) -> -8640
A32: Insurance | B32: SUMIFS on Forecast_Lines | C32: =SUMIFS(Forecast_Lines!$J$4:$J$377,Forecast_Lines!$D$4:$D$377,"Payment",Forecast_Lines!$E$4:$E$377,"Insurance",Forecast_Lines!$O$4:$O$377,C$4) -> 0 | D32: =SUMIFS(Forecast_Lines!$J$4:$J$377,Forecast_Lines!$D$4:$D$377,"Payment",Forecast_Lines!$E$4:$E$377,"Insurance",Forecast_Lines!$O$4:$O$377,D$4) -> 0 | E32: =SUMIFS(Forecast_Lines!$J$4:$J$377,Forecast_Lines!$D$4:$D$377,"Payment",Forecast_Lines!$E$4:$E$377,"Insurance",Forecast_Lines!$O$4:$O$377,E$4) -> 0 | F32: =SUMIFS(Forecast_Lines!$J$4:$J$377,Forecast_Lines!$D$4:$D$377,"Payment",Forecast_Lines!$E$4:$E$377,"Insurance",Forecast_Lines!$O$4:$O$377,F$4) -> 0 | G32: =SUMIFS(Forecast_Lines!$J$4:$J$377,Forecast_Lines!$D$4:$D$377,"Payment",Forecast_Lines!$E$4:$E$377,"Insurance",Forecast_Lines!$O$4:$O$377,G$4) -> 0 | H32: =SUMIFS(Forecast_Lines!$J$4:$J$377,Forecast_Lines!$D$4:$D$377,"Payment",Forecast_Lines!$E$4:$E$377,"Insurance",Forecast_Lines!$O$4:$O$377,H$4) -> 0 | I32: =SUMIFS(Forecast_Lines!$J$4:$J$377,Forecast_Lines!$D$4:$D$377,"Payment",Forecast_Lines!$E$4:$E$377,"Insurance",Forecast_Lines!$O$4:$O$377,I$4) -> 0 | J32: =SUMIFS(Forecast_Lines!$J$4:$J$377,Forecast_Lines!$D$4:$D$377,"Payment",Forecast_Lines!$E$4:$E$377,"Insurance",Forecast_Lines!$O$4:$O$377,J$4) -> 0 | ... O32: =SUMIFS(Forecast_Lines!$J$4:$J$377,Forecast_Lines!$D$4:$D$377,"Payment",Forecast_Lines!$E$4:$E$377,"Insurance",Forecast_Lines!$O$4:$O$377,O$4) -> -7800 | P32: =SUM(C32:O32) -> -7800
A33: Business property tax | B33: SUMIFS on Forecast_Lines | C33: =SUMIFS(Forecast_Lines!$J$4:$J$377,Forecast_Lines!$D$4:$D$377,"Payment",Forecast_Lines!$E$4:$E$377,"Business property tax",Forecast_Lines!$O$4:$O$377,C$4) -> 0 | D33: =SUMIFS(Forecast_Lines!$J$4:$J$377,Forecast_Lines!$D$4:$D$377,"Payment",Forecast_Lines!$E$4:$E$377,"Business property tax",Forecast_Lines!$O$4:$O$377,D$4) -> 0 | E33: =SUMIFS(Forecast_Lines!$J$4:$J$377,Forecast_Lines!$D$4:$D$377,"Payment",Forecast_Lines!$E$4:$E$377,"Business property tax",Forecast_Lines!$O$4:$O$377,E$4) -> 0 | F33: =SUMIFS(Forecast_Lines!$J$4:$J$377,Forecast_Lines!$D$4:$D$377,"Payment",Forecast_Lines!$E$4:$E$377,"Business property tax",Forecast_Lines!$O$4:$O$377,F$4) -> 0 | G33: =SUMIFS(Forecast_Lines!$J$4:$J$377,Forecast_Lines!$D$4:$D$377,"Payment",Forecast_Lines!$E$4:$E$377,"Business property tax",Forecast_Lines!$O$4:$O$377,G$4) -> 0 | H33: =SUMIFS(Forecast_Lines!$J$4:$J$377,Forecast_Lines!$D$4:$D$377,"Payment",Forecast_Lines!$E$4:$E$377,"Business property tax",Forecast_Lines!$O$4:$O$377,H$4) -> 0 | I33: =SUMIFS(Forecast_Lines!$J$4:$J$377,Forecast_Lines!$D$4:$D$377,"Payment",Forecast_Lines!$E$4:$E$377,"Business property tax",Forecast_Lines!$O$4:$O$377,I$4) -> 0 | J33: =SUMIFS(Forecast_Lines!$J$4:$J$377,Forecast_Lines!$D$4:$D$377,"Payment",Forecast_Lines!$E$4:$E$377,"Business property tax",Forecast_Lines!$O$4:$O$377,J$4) -> 0 | ... O33: =SUMIFS(Forecast_Lines!$J$4:$J$377,Forecast_Lines!$D$4:$D$377,"Payment",Forecast_Lines!$E$4:$E$377,"Business property tax",Forecast_Lines!$O$4:$O$377,O$4) -> 0 | P33: =SUM(C33:O33) -> -6200
A34: Total payments | C34: =SUM(C20:C33) -> -141822.15 | D34: =SUM(D20:D33) -> -10711.58 | E34: =SUM(E20:E33) -> -439303.92 | F34: =SUM(F20:F33) -> -77498.47 | G34: =SUM(G20:G33) -> -29012.02 | H34: =SUM(H20:H33) -> -291169.89 | I34: =SUM(I20:I33) -> -166272.24 | J34: =SUM(J20:J33) -> -279685.32 | ... O34: =SUM(O20:O33) -> -112227.76 | P34: =SUM(C34:O34) -> -2273028
A35: Net cash flow | C35: =C18+C34 -> -98400.15 | D35: =D18+D34 -> 166336.42 | E35: =E18+E34 -> -348319.92 | F35: =F18+F34 -> 69933.53 | G35: =G18+G34 -> 83183.98 | H35: =H18+H34 -> -135337.89 | I35: =I18+I34 -> 224739.76 | J35: =J18+J34 -> -179051.32 | ... O35: =O18+O34 -> 75052.24 | P35: =SUM(C35:O35) -> -86296.02
A36: CLOSING BALANCE — base | B36: opening + receipts + payments | C36: =C9+C35 -> 282840.5 | D36: =D9+D35 -> 449176.92 | E36: =E9+E35 -> 100857 | F36: =F9+F35 -> 170790.53 | G36: =G9+G35 -> 253974.51 | H36: =H9+H35 -> 118636.62 | I36: =I9+I35 -> 343376.38 | J36: =J9+J35 -> 164325.06 | ... O36: =O9+O35 -> 294944.63
A37: Minimum cash buffer | B37: Assumptions A04 | C37: =Assumptions!$C$5 -> 100000 | D37: =Assumptions!$C$5 -> 100000 | E37: =Assumptions!$C$5 -> 100000 | F37: =Assumptions!$C$5 -> 100000 | G37: =Assumptions!$C$5 -> 100000 | H37: =Assumptions!$C$5 -> 100000 | I37: =Assumptions!$C$5 -> 100000 | J37: =Assumptions!$C$5 -> 100000 | ... O37: =Assumptions!$C$5 -> 100000
A38: Headroom above buffer — base | C38: =C36-C37 -> 182840.5 | D38: =D36-D37 -> 349176.92 | E38: =E36-E37 -> 857 | F38: =F36-F37 -> 70790.53 | G38: =G36-G37 -> 153974.51 | H38: =H36-H37 -> 18636.62 | I38: =I36-I37 -> 243376.38 | J38: =J36-J37 -> 64325.06 | ... O38: =O36-O37 -> 194944.63
A39: Flag — base | C39: =IF(C36<-Assumptions!$C$6,"BEYOND OVERDRAFT",IF(C36<0,"OVERDRAFT",IF(C36<C37,"BELOW BUFFER","ok"))) -> ok | D39: =IF(D36<-Assumptions!$C$6,"BEYOND OVERDRAFT",IF(D36<0,"OVERDRAFT",IF(D36<D37,"BELOW BUFFER","ok"))) -> ok | E39: =IF(E36<-Assumptions!$C$6,"BEYOND OVERDRAFT",IF(E36<0,"OVERDRAFT",IF(E36<E37,"BELOW BUFFER","ok"))) -> ok | F39: =IF(F36<-Assumptions!$C$6,"BEYOND OVERDRAFT",IF(F36<0,"OVERDRAFT",IF(F36<F37,"BELOW BUFFER","ok"))) -> ok | G39: =IF(G36<-Assumptions!$C$6,"BEYOND OVERDRAFT",IF(G36<0,"OVERDRAFT",IF(G36<G37,"BELOW BUFFER","ok"))) -> ok | H39: =IF(H36<-Assumptions!$C$6,"BEYOND OVERDRAFT",IF(H36<0,"OVERDRAFT",IF(H36<H37,"BELOW BUFFER","ok"))) -> ok | I39: =IF(I36<-Assumptions!$C$6,"BEYOND OVERDRAFT",IF(I36<0,"OVERDRAFT",IF(I36<I37,"BELOW BUFFER","ok"))) -> ok | J39: =IF(J36<-Assumptions!$C$6,"BEYOND OVERDRAFT",IF(J36<0,"OVERDRAFT",IF(J36<J37,"BELOW BUFFER","ok"))) -> ok | ... O39: =IF(O36<-Assumptions!$C$6,"BEYOND OVERDRAFT",IF(O36<0,"OVERDRAFT",IF(O36<O37,"BELOW BUFFER","ok"))) -> ok
A41: SCENARIO S1 — Lumen Hospitality pays 45 days later than usual (Assumptions S01)
A42: Opening balance | C42: =Assumptions!$C$4 -> 381240.65 | D42: =C45 -> 282840.5 | E42: =D45 -> 449176.92 | F42: =E45 -> 100857 | G42: =F45 -> 170790.53 | H42: =G45 -> 253974.51 | I42: =H45 -> 118636.62 | J42: =I45 -> 112976.38 | K42: =J45 -> -66074.94 | ... O42: =N45 -> -10507.61
A43: Total receipts | B43: SUMIFS on Q | C43: =SUMIFS(Forecast_Lines!$J$4:$J$377,Forecast_Lines!$D$4:$D$377,"Receipt",Forecast_Lines!$U$4:$U$377,"Yes",Forecast_Lines!$Q$4:$Q$377,C$4) -> 43422 | D43: =SUMIFS(Forecast_Lines!$J$4:$J$377,Forecast_Lines!$D$4:$D$377,"Receipt",Forecast_Lines!$U$4:$U$377,"Yes",Forecast_Lines!$Q$4:$Q$377,D$4) -> 177048 | E43: =SUMIFS(Forecast_Lines!$J$4:$J$377,Forecast_Lines!$D$4:$D$377,"Receipt",Forecast_Lines!$U$4:$U$377,"Yes",Forecast_Lines!$Q$4:$Q$377,E$4) -> 90984 | F43: =SUMIFS(Forecast_Lines!$J$4:$J$377,Forecast_Lines!$D$4:$D$377,"Receipt",Forecast_Lines!$U$4:$U$377,"Yes",Forecast_Lines!$Q$4:$Q$377,F$4) -> 147432 | G43: =SUMIFS(Forecast_Lines!$J$4:$J$377,Forecast_Lines!$D$4:$D$377,"Receipt",Forecast_Lines!$U$4:$U$377,"Yes",Forecast_Lines!$Q$4:$Q$377,G$4) -> 112196 | H43: =SUMIFS(Forecast_Lines!$J$4:$J$377,Forecast_Lines!$D$4:$D$377,"Receipt",Forecast_Lines!$U$4:$U$377,"Yes",Forecast_Lines!$Q$4:$Q$377,H$4) -> 155832 | I43: =SUMIFS(Forecast_Lines!$J$4:$J$377,Forecast_Lines!$D$4:$D$377,"Receipt",Forecast_Lines!$U$4:$U$377,"Yes",Forecast_Lines!$Q$4:$Q$377,I$4) -> 160612 | J43: =SUMIFS(Forecast_Lines!$J$4:$J$377,Forecast_Lines!$D$4:$D$377,"Receipt",Forecast_Lines!$U$4:$U$377,"Yes",Forecast_Lines!$Q$4:$Q$377,J$4) -> 100634 | ... O43: =SUMIFS(Forecast_Lines!$J$4:$J$377,Forecast_Lines!$D$4:$D$377,"Receipt",Forecast_Lines!$U$4:$U$377,"Yes",Forecast_Lines!$Q$4:$Q$377,O$4) -> 187280 | P43: =SUM(C43:O43) -> 1956332
...

Sheet Warning
B2: ⚠ Cash shortfall warning — raised Fri 9 Oct 2026
B3: Generated from the forecast run (template text filled with forecast numbers; every number links to Forecast_13W / Forecast_Lines). Advisory only — the CFO decides.
B5: Headline | C5: If Lumen Hospitality pays its €230,400 delivery invoice 45 days later than usual, cash falls below the €100k buffer in week 8 (week of 30 Nov 2026) and reaches −€66,075 — €166,075 short of the buffer and inside the overdraft.
B6: Lead time | C6: 7 weeks before the breach — enough time to act without emergency borrowing.
B7: Main cause | C7: Timing, not profitability: (1) the €230,400 Lumen receipt (invoice INV-2026-1149) moves from week 7 to after week 13; (2) it coincides with the €155,000 Holzwerk Bayern timber pre-order paid on 19 Nov (week 6); (3) week 8 itself is heavy: Holzwerk Bayern GmbH €122,068, Employees (38 FTE) €106,000, Aciers Rhône-Métal €38,640.
B8: Profit vs cash | C8: Q4 2026 still shows a net profit of ≈ €182k in the P&L: the sales are real and invoiced, but the cash has not arrived yet.
B9: How sure are we? | C9: In the base case the lowest point is €100,857 in week 3 — just above the buffer, with a 25% chance of dipping below it that week (41% chance of at least one week below the buffer in 13 weeks). If the Lumen delay happens, a breach is near-certain (100% of simulations). If contractors also slow down (S2), the overdraft is used in 100% of simulations and the balance reaches about −€200,127, beyond the €150k facility — so S2 cannot be solved by the overdraft alone.
B10: Watch-list | C10: Nova Interiors is paying slower (≈ 22 days late in 2025 → ≈ 34 days in Q3 2026). Two invoices are disputed (€32k) and excluded from expected receipts until resolved.
B11: What to do | C11: See CFO_Actions. The no-regret package A1–A4 keeps S1 at ≈ €100k (the buffer); adding A6 (finance the Lumen invoice) restores headroom. Nothing is executed without the CFO's decision.
B12: Assumptions behind this | C12: Assumptions A01–A12 and scenario S01 (45 days) — change them in 'Assumptions' to test other delays; Forecast_13W updates automatically.
B14: Live checks (formulas)
B15: First week below buffer (S1) | C15: =Forecast_13W!C81 -> 8
B16: Lowest balance (S1) | C16: =MIN(Forecast_13W!C45:O45) -> -66074.94
B17: Lowest balance (base) | C17: =MIN(Forecast_13W!C36:O36) -> 100857
B18: Lumen delay assumed (days) | C18: =Assumptions!$C$14 -> 45

Sheet CFO_Actions
A1: Options for the CFO to evaluate under scenario S1 — the tool proposes, the CFO decides. Nothing is sent to a bank, customer or supplier automatically.
A2: S1 lowest balance without action: €-66,075 (week 8). 'Effect on lowest balance' = how much the lowest weekly balance of S1 improves if the action alone is taken.
A4: id | B4: action | C4: what it means | D4: effect on lowest balance (€) | E4: new lowest balance (€) | F4: week of new low | G4: cost / trade-off | H4: confidence | I4: owner | J4: status | K4: CFO decision | L4: decided by | M4: date | N4: CFO comment
A5: A1 | B5: Get the two slowest contractors to pay on time | C5: Reminder 5 days before due date + phone follow-up for Bâtir Bureaux and Nova Interiors (they pay 22–34 days late); goal: half of their invoices due in the window paid on the due date. Late-payment penalties and the €40 fixed fee are in the terms of sale as leverage. | D5: 81840 | E5: 15765 | F5: 8 | G5: Staff time; relationship risk is low (penalties are contractual) | H5: Medium | I5: Accountant + sales director | J5: Proposed – awaiting CFO decision
A6: A2 | B6: Fix the rejected hospital invoice | C6: Re-submit CHU Vallée du Rhône invoice in Chorus Pro with the missing PO number (€16.8k). | D6: 16824 | E6: -49251 | F6: 8 | G6: None | H6: High | I6: Accountant | J6: Proposed – awaiting CFO decision
A7: A3 | B7: Defer the edge-bander deposit | C7: Move the €34.6k machine deposit from 25 Nov to January (delivery slips ~6 weeks). | D7: 34560 | E7: -31515 | F7: 8 | G7: Machine arrives later; possible price revision | H7: High | I7: CEO / CFO | J7: Proposed – awaiting CFO decision
A8: A4 | B8: Split the Holzwerk timber bill | C8: Ask Holzwerk Bayern to accept 50% on 19 Nov and 50% four weeks later. | D8: 55567 | E8: -10508 | F8: 12 | G8: May lose part of the 3% volume discount (≤ €4.7k) | H8: Medium | I8: CFO + purchasing | J8: Proposed – awaiting CFO decision
A9: A5 | B9: Early-payment offer to Lumen | C9: Offer Lumen a 2% discount if the €230k delivery invoice is paid on its usual date, and fix the installation snags fast. | D9: 166932 | E9: 100857 | F9: 3 | G9: ≈ €4.6k discount | H9: Low–Medium | I9: CEO (relationship owner) | J9: Proposed – awaiting CFO decision
A10: A6 | B10: Finance the Lumen invoice | C10: Use invoice financing (factoring) on the €230k Lumen invoice: ~80% advanced in week 4. | D10: 166932 | E10: 100857 | F10: 3 | G10: ≈ €3–4k fees + interest; customer may be notified | H10: High (if bank agrees) | I10: CFO + bank | J10: Proposed – awaiting CFO decision
A11: A7 | B11: Draw on the €150k overdraft | C11: Covers any balance below zero; does not restore the €100k buffer. | D11: 0 | E11: -66075 | F11: 8 | G11: ≈ 4.6% p.a. on amounts drawn (S2 stress: ≈ €937 for the quarter); signals stress to the bank | H11: High (facility in place) | I11: CFO | J11: Proposed – awaiting CFO decision
A13: Packages
B14: A1–A4 (no-regret: collections, dispute fix, defer capex, split timber bill) | E14: 99664 | F14: 12
B15: A1–A4 + A6 (also finance the Lumen invoice) | E15: 106677 | F15: 3
B16: Stress S2 with A1–A4 + A6 → remaining gap covered by A7 overdraft | E16: -26835
A18: Effects are estimates from the forecast engine (deterministic S1). Actions interact, so package effects are not the sum of single effects. Legend: yellow = CFO input.

Sheet Forecast_Lines
A1: Every cash line behind the 13-week forecast. Expected date (base) = due date + the customer's median days late over the last 12 months (for invoices already overdue: median of the longer past delays). Scenario dates and all week numbers are formulas linked to Assumptions.
A3: line_id | B3: source_sheet | C3: source_id | D3: flow | E3: category | F3: counterparty | G3: customer_id | H3: amount_eur | I3: probability | J3: expected_value_eur | K3: due_date | L3: days_late_now | M3: assumed_days_late | N3: expected_date | O3: week | P3: expected_date_S1 | Q3: week_S1 | R3: expected_date_S2 | S3: week_S2 | T3: status | U3: included_in_base | V3: description
A4: L0335 | B4: Scheduled_Payments | C4: PAY-001 | D4: Payment | E4: Equipment lease | F4: LeasEquip France | H4: -3840 | I4: 1 | J4: =H4*I4 -> -3840 | K4: 46307 | N4: 46307 | O4: =IF(INT((N4-Assumptions!$C$2)/7)+1>Assumptions!$C$3,"after W13",INT((N4-Assumptions!$C$2)/7)+1) -> 1 | P4: =IF(AND(D4="Receipt",G4="C01"),WORKDAY(N4+Assumptions!$C$14-1,1),N4) -> 46307 | Q4: =IF(INT((P4-Assumptions!$C$2)/7)+1>Assumptions!$C$3,"after W13",INT((P4-Assumptions!$C$2)/7)+1) -> 1 | R4: =IF(AND(D4="Receipt",OR(G4="C01",G4="C02",G4="C03",G4="C04",G4="C07")),WORKDAY(N4+IF(G4="C01",Assumptions!$C$14,Assumptions!$C$15)-1,1),N4) -> 46307 | S4: =IF(INT((R4-Assumptions!$C$2)/7)+1>Assumptions!$C$3,"after W13",INT((R4-Assumptions!$C$2)/7)+1) -> 1 | T4: Contractual / statutory | U4: Yes
A5: L0019 | B5: AR_Invoices | C5: INV-2026-1119 | D5: Receipt | E5: Customer – Furniture distributor | F5: Officea Distribution | G5: C05 | H5: 7836 | I5: 1 | J5: =H5*I5 -> 7836 | K5: 46306 | L5: 0 | M5: 0 | N5: 46307 | O5: =IF(INT((N5-Assumptions!$C$2)/7)+1>Assumptions!$C$3,"after W13",INT((N5-Assumptions!$C$2)/7)+1) -> 1 | P5: =IF(AND(D5="Receipt",G5="C01"),WORKDAY(N5+Assumptions!$C$14-1,1),N5) -> 46307 | Q5: =IF(INT((P5-Assumptions!$C$2)/7)+1>Assumptions!$C$3,"after W13",INT((P5-Assumptions!$C$2)/7)+1) -> 1 | R5: =IF(AND(D5="Receipt",OR(G5="C01",G5="C02",G5="C03",G5="C04",G5="C07")),WORKDAY(N5+IF(G5="C01",Assumptions!$C$14,Assumptions!$C$15)-1,1),N5) -> 46307 | S5: =IF(INT((R5-Assumptions!$C$2)/7)+1>Assumptions!$C$3,"after W13",INT((R5-Assumptions!$C$2)/7)+1) -> 1 | T5: Open | U5: Yes | V5: Furniture order
A6: L0040 | B6: AR_Invoices | C6: INV-2026-1142 | D6: Receipt | E6: Customer – Office fit-out contractor | F6: Studio Kaya Design | G6: C07 | H6: 8220 | I6: 1 | J6: =H6*I6 -> 8220 | K6: 46305 | L6: 0 | M6: 3 | N6: 46308 | O6: =IF(INT((N6-Assumptions!$C$2)/7)+1>Assumptions!$C$3,"after W13",INT((N6-Assumptions!$C$2)/7)+1) -> 1 | P6: =IF(AND(D6="Receipt",G6="C01"),WORKDAY(N6+Assumptions!$C$14-1,1),N6) -> 46308 | Q6: =IF(INT((P6-Assumptions!$C$2)/7)+1>Assumptions!$C$3,"after W13",INT((P6-Assumptions!$C$2)/7)+1) -> 1 | R6: =IF(AND(D6="Receipt",OR(G6="C01",G6="C02",G6="C03",G6="C04",G6="C07")),WORKDAY(N6+IF(G6="C01",Assumptions!$C$14,Assumptions!$C$15)-1,1),N6) -> 46323 | S6: =IF(INT((R6-Assumptions!$C$2)/7)+1>Assumptions!$C$3,"after W13",INT((R6-Assumptions!$C$2)/7)+1) -> 3 | T6: Open | U6: Yes | V6: Furniture order
A7: L0336 | B7: Scheduled_Payments | C7: PAY-002 | D7: Payment | E7: Card & sundry spending | F7: Fuel, travel, consumables | H7: -4700 | I7: 1 | J7: =H7*I7 -> -4700 | K7: 46309 | N7: 46309 | O7: =IF(INT((N7-Assumptions!$C$2)/7)+1>Assumptions!$C$3,"after W13",INT((N7-Assumptions!$C$2)/7)+1) -> 1 | P7: =IF(AND(D7="Receipt",G7="C01"),WORKDAY(N7+Assumptions!$C$14-1,1),N7) -> 46309 | Q7: =IF(INT((P7-Assumptions!$C$2)/7)+1>Assumptions!$C$3,"after W13",INT((P7-Assumptions!$C$2)/7)+1) -> 1 | R7: =IF(AND(D7="Receipt",OR(G7="C01",G7="C02",G7="C03",G7="C04",G7="C07")),WORKDAY(N7+IF(G7="C01",Assumptions!$C$14,Assumptions!$C$15)-1,1),N7) -> 46309 | S7: =IF(INT((R7-Assumptions!$C$2)/7)+1>Assumptions!$C$3,"after W13",INT((R7-Assumptions!$C$2)/7)+1) -> 1 | T7: Estimate (run-rate) | U7: Yes | V7: Run-rate estimate (avg of last 26 weeks, rounded)
